INFO - main.py - 2024-06-20 05:04:17,094 - Using device: cuda:1
INFO - main.py - 2024-06-20 05:04:17,097 - Writing log file to market_ddim/logs/market
INFO - main.py - 2024-06-20 05:04:17,098 - Exp instance id = 62572
INFO - main.py - 2024-06-20 05:04:17,098 - Exp comment = 
ERROR - main.py - 2024-06-20 05:04:18,509 - Traceback (most recent call last):
  File "/workspace/ddim/main.py", line 242, in main
    runner.train()
  File "/workspace/ddim/runners/diffusion.py", line 154, in train
    loss = loss_registry[config.model.type](model, x, t, e, b)
  File "/workspace/ddim/functions/losses.py", line 11, in noise_estimation_loss
    output = model(x, t.float())
  File "/opt/conda/lib/python3.10/site-packages/torch/nn/modules/module.py", line 1511, in _wrapped_call_impl
    return self._call_impl(*args, **kwargs)
  File "/opt/conda/lib/python3.10/site-packages/torch/nn/modules/module.py", line 1520, in _call_impl
    return forward_call(*args, **kwargs)
  File "/workspace/ddim/models/diffusion.py", line 302, in forward
    assert x.shape[2] == self.resolution[0] and x.shape[3] == self.resolution[1]
AssertionError

